<?xml version="1.0" encoding="utf-8"?>
<!-- This URDF was automatically created by SolidWorks to URDF Exporter! Originally created by Stephen Brawner (brawner@gmail.com) 
     Commit Version: 1.6.0-4-g7f85cfe  Build Version: 1.6.7995.38578
     For more information, please see http://wiki.ros.org/sw_urdf_exporter -->
<robot
  name="Exoskeleton_Assembly_urdf">
  <link
    name="base_link">
    <inertial>
      <origin
        xyz="-0.027634 0.018512 0.015733"
        rpy="0 0 0" />
      <mass
        value="2.5953" />
      <inertia
        ixx="0.014094"
        ixy="-2.1768E-05"
        ixz="8.9157E-09"
        iyy="0.007423"
        iyz="4.6457E-08"
        izz="0.016086" />
    </inertial>
    <visual>
      <origin
        xyz="0 0 0"
        rpy="0 0 0" />
      <geometry>
        <mesh
          filename="package://Exoskeleton_Assembly_urdf/meshes/base_link.STL" />
      </geometry>
      <material
        name="">
        <color
          rgba="0.098039 0.098039 0.098039 1" />
      </material>
    </visual>
    <collision>
      <origin
        xyz="0 0 0"
        rpy="0 0 0" />
      <geometry>
        <mesh
          filename="package://Exoskeleton_Assembly_urdf/meshes/base_link.STL" />
      </geometry>
    </collision>
  </link>
  <link
    name="right_thigh">
    <inertial>
      <origin
        xyz="8.0718E-05 0.02689 -0.28057"
        rpy="0 0 0" />
      <mass
        value="1.0471" />
      <inertia
        ixx="0.0045052"
        ixy="1.6061E-08"
        ixz="-6.8701E-07"
        iyy="0.0048803"
        iyz="-4.551E-05"
        izz="0.0045452" />
    </inertial>
    <visual>
      <origin
        xyz="0 0 0"
        rpy="0 0 0" />
      <geometry>
        <mesh
          filename="package://Exoskeleton_Assembly_urdf/meshes/right_thigh.STL" />
      </geometry>
      <material
        name="">
        <color
          rgba="0.96471 0.96471 0.95294 1" />
      </material>
    </visual>
    <collision>
      <origin
        xyz="0 0 0"
        rpy="0 0 0" />
      <geometry>
        <mesh
          filename="package://Exoskeleton_Assembly_urdf/meshes/right_thigh.STL" />
      </geometry>
    </collision>
  </link>
  <joint
    name="right_hip_joint"
    type="revolute">
    <origin
      xyz="0.054114 -0.21135 -0.082367"
      rpy="0 0 0" />
    <parent
      link="base_link" />
    <child
      link="right_thigh" />
    <axis
      xyz="0 -1 0" />
    <limit
      lower="-1.0472"
      upper="1.57"
      effort="300"
      velocity="12.56" />
  </joint>
  <link
    name="right_shank">
    <inertial>
      <origin
        xyz="0.00012029 0.085772 -0.19514"
        rpy="0 0 0" />
      <mass
        value="0.68028" />
      <inertia
        ixx="0.0038839"
        ixy="-2.2537E-09"
        ixz="-7.3385E-07"
        iyy="0.003922"
        iyz="-4.3787E-06"
        izz="0.0040903" />
    </inertial>
    <visual>
      <origin
        xyz="0 0 0"
        rpy="0 0 0" />
      <geometry>
        <mesh
          filename="package://Exoskeleton_Assembly_urdf/meshes/right_shank.STL" />
      </geometry>
      <material
        name="">
        <color
          rgba="0.96471 0.96471 0.95294 1" />
      </material>
    </visual>
    <collision>
      <origin
        xyz="0 0 0"
        rpy="0 0 0" />
      <geometry>
        <mesh
          filename="package://Exoskeleton_Assembly_urdf/meshes/right_shank.STL" />
      </geometry>
    </collision>
  </link>
  <joint
    name="right_knee_joint"
    type="revolute">
    <origin
      xyz="0 -0.0035 -0.465"
      rpy="0 0 0" />
    <parent
      link="right_thigh" />
    <child
      link="right_shank" />
    <axis
      xyz="0 1 0" />
    <limit
      lower="0"
      upper="2.0944"
      effort="200"
      velocity="12.56" />
  </joint>
  <link
    name="left_thigh">
    <inertial>
      <origin
        xyz="-0.00021719 -0.02703 -0.28056"
        rpy="0 0 0" />
      <mass
        value="1.0471" />
      <inertia
        ixx="0.0045052"
        ixy="-2.3619E-08"
        ixz="6.8962E-07"
        iyy="0.0048803"
        iyz="4.5499E-05"
        izz="0.0045452" />
    </inertial>
    <visual>
      <origin
        xyz="0 0 0"
        rpy="0 0 0" />
      <geometry>
        <mesh
          filename="package://Exoskeleton_Assembly_urdf/meshes/left_thigh.STL" />
      </geometry>
      <material
        name="">
        <color
          rgba="0.96471 0.96471 0.95294 1" />
      </material>
    </visual>
    <collision>
      <origin
        xyz="0 0 0"
        rpy="0 0 0" />
      <geometry>
        <mesh
          filename="package://Exoskeleton_Assembly_urdf/meshes/left_thigh.STL" />
      </geometry>
    </collision>
  </link>
  <joint
    name="left_hip_joint"
    type="revolute">
    <origin
      xyz="0.054114 0.24688 -0.082367"
      rpy="0 0 0" />
    <parent
      link="base_link" />
    <child
      link="left_thigh" />
    <axis
      xyz="0 1 0" />
    <limit
      lower="-1.57"
      upper="1.0472"
      effort="300"
      velocity="12.56" />
  </joint>
  <link
    name="left_shank">
    <inertial>
      <origin
        xyz="-0.00015288 -0.085744 -0.19515"
        rpy="0 0 0" />
      <mass
        value="0.67979" />
      <inertia
        ixx="0.0038839"
        ixy="-2.2537E-09"
        ixz="7.3385E-07"
        iyy="0.003922"
        iyz="4.3787E-06"
        izz="0.0040903" />
    </inertial>
    <visual>
      <origin
        xyz="0 0 0"
        rpy="0 0 0" />
      <geometry>
        <mesh
          filename="package://Exoskeleton_Assembly_urdf/meshes/left_shank.STL" />
      </geometry>
      <material
        name="">
        <color
          rgba="0.96471 0.96471 0.95294 1" />
      </material>
    </visual>
    <collision>
      <origin
        xyz="0 0 0"
        rpy="0 0 0" />
      <geometry>
        <mesh
          filename="package://Exoskeleton_Assembly_urdf/meshes/left_shank.STL" />
      </geometry>
    </collision>
  </link>
  <joint
    name="left_knee_joint"
    type="revolute">
    <origin
      xyz="-0.0004 0.0031 -0.465"
      rpy="0 0 0" />
    <parent
      link="left_thigh" />
    <child
      link="left_shank" />
    <axis
      xyz="0 -1 0" />
    <limit
      lower="-2.0944"
      upper="0"
      effort="200"
      velocity="12.56" />
  </joint>
</robot>